Workbook

Sheet SUMMARY
B1: RTD | J1: Defeat | M1: Defeat | N1: Defeat | O1: Defeat
B3: Row Labels | C3: Sum of Points | E3: Row Labels | F3: Row Labels | G3: Row Labels | J3: Row Labels | K3: Sum of Points | M3: Row Labels | N3: Row Labels | O3: Row Labels
B4: Digital skills | C4: 18 | E4: Communication | F4: Confidence | G4: Confidence | J4: Digital skills | K4: 15 | M4: Confidence | N4: Confidence | O4: Confidence
B5: Data Logger | C5: 6 | E5: Confidence | F5: Creativity | G5: Decision Making | J5: Document Designer | K5: 6 | M5: Decision Making | N5: Creativity | O5: Decision Making
B6: Memory Maker | C6: 6 | E6: Decision Making | F6: Decision Making | G6: Digital Literacy | J6: Research Ranger | K6: 3 | M6: Digital Literacy | N6: Digital Literacy | O6: Digital Literacy
B7: Prep Master | C7: 6 | E7: Digital Literacy | F7: Digital Literacy | G7: Leadership | J7: Storyteller | K7: 6 | M7: Planning & Organising | N7: Leadership | O7: Leadership
B8: Esports Citizen | C8: 15 | E8: Planning & Organising | F8: Leadership | G8: Problem Solving | J8: Esports Citizen | K8: 15 | M8: Problem Solving | N8: Planning & Organising | O8: Problem Solving
B9: Code Keeper | C9: 6 | E9: Resilience | F9: Planning & Organising | G9: Self-Management | J9: Supportive Teammate | K9: 3 | M9: Resilience | N9: Resilience | O9: Self-Management
B10: Conduct Creator | C10: 6 | E10: Self-Management | F10: Resilience | G10: Working with Others | J10: Top Citizen | K10: 6 | M10: Self-Management | N10: Self-Management | O10: Working with Others
B11: Positve Voice | C11: 3 | E11: Working with Others | F11: Self-Management | G11: Grand Total | J11: World Code | K11: 6 | M11: Working with Others | N11: Working with Others | O11: Grand Total
B12: Game Mastery | C12: 33 | E12: Grand Total | F12: Grand Total | J12: Game Mastery | K12: 30 | M12: Grand Total | N12: Grand Total
B13: Basic Mechanics | C13: 6 | J13: Base Builder | K13: 3
B14: End Of The Road | C14: 15 | J14: Dragon Prepared | K14: 6
B15: Master Plan | C15: 6 | J15: Dragon Slayer | K15: 15
B16: Skill Evaluation | C16: 6 | J16: Nether Ready | K16: 6
B17: Personal Development | C17: 18 | J17: Personal Development | K17: 15
B18: Goal Scorer | C18: 6 | J18: Goal Setter | K18: 3
B19: Learn In Action | C19: 6 | J19: Reflection | K19: 6
B20: Player Performance | C20: 6 | J20: Resilient | K20: 6
B21: Teamwork | C21: 15 | J21: Teamwork | K21: 30
B22: Duo Snatcher | C22: 3 | J22: Completed It First | K22: 15
B23: Role Model | C23: 6 | J23: Mission Teamate | K23: 6
B24: Tactical Minds | C24: 6 | J24: Role Player | K24: 6
B25: Grand Total | C25: 99 | J25: Team Planner | K25: 3
J26: Grand Total | K26: 105
E28: 3 per module
P31: terms | S31: RTD | T31: Module
P32: league
B33: Skill 1 | C33: Decision Making | F33: The 5 main badge categories (Game Mastery, Teamwork, Esports Citizen, Personal Development, Digital Skills) are constant across all activities and modules. | P33: module | Q33: Road to Diamond
B34: Skill 2 | C34: Decision Making | P34: badges | S34: Module | T34: schedule (say 12 weeks)
B35: Skill 3 | C35: Decision Making | F35: 3+ sub badges under each badge category | P35: subbadges | S35: Module | T35: point tracker
P36: legacypoints
B37: Row Labels | C37: Sum of Points | F37: Legacy Points is used to carry forward points from previous games | P37: skills
B38: Grand Total | P38: sports groups
F39: each sub badge has a fixed point and is either awareded in complete or not awarded at all | P39: LEVEL - plat, diamond
F41: sub badges are unique in each game
F43: the game is runs for x weeks, each week there is a focus on a certain sub -badge
V50: leagacy
N51: table1 | P51: table2 1: many | S51: table 3 | V51: static table | W51: badge1 | X51: badge2
N52: Skills table | P52: subbadge -> skills map | S52: sub badge and points | V52: player1 | W52: 12 | X52: 13
...

Sheet Sheet2
B4: eGAME | C4: Main Badge | D4: Sub Badge | E4: Points | J4: Column Labels
B5: RTD | C5: Game Mastery | D5: Skill Evaluation | E5: 6 | J5: Digital skills | L5: Esports Citizen | N5: Game Mastery | P5: Personal Development | R5: Teamwork | T5: Total Sum of Points | U5: Total Count of Points2
B6: RTD | C6: Game Mastery | D6: Master Plan | E6: 6 | I6: Row Labels | J6: Sum of Points | K6: Count of Points2 | L6: Sum of Points | M6: Count of Points2 | N6: Sum of Points | O6: Count of Points2 | P6: Sum of Points | Q6: Count of Points2 | R6: Sum of Points | S6: Count of Points2
B7: RTD | C7: Game Mastery | D7: Basic Mechanics | E7: 6 | I7: Base Builder | N7: 3 | O7: 1 | T7: 3 | U7: 1
B8: RTD | C8: Teamwork | D8: Duo Snatcher | E8: 3 | I8: Basic Mechanics | N8: 6 | O8: 1 | T8: 6 | U8: 1
B9: RTD | C9: Teamwork | D9: Tactical Minds | E9: 6 | I9: Code Keeper | L9: 6 | M9: 1 | T9: 6 | U9: 1
B10: RTD | C10: Teamwork | D10: Role Model | E10: 6 | I10: Completed It First | R10: 15 | S10: 1 | T10: 15 | U10: 1
B11: RTD | C11: Personal Development | D11: Learn In Action | E11: 6 | I11: Conduct Creator | L11: 6 | M11: 1 | T11: 6 | U11: 1
B12: RTD | C12: Personal Development | D12: Goal Scorer | E12: 6 | I12: Data Logger | J12: 6 | K12: 1 | T12: 6 | U12: 1
B13: RTD | C13: Personal Development | D13: Player Performance | E13: 6 | I13: Document Designer | J13: 6 | K13: 1 | T13: 6 | U13: 1
B14: RTD | C14: Esports Citizen | D14: Conduct Creator | E14: 6 | I14: Dragon Prepared | N14: 6 | O14: 1 | T14: 6 | U14: 1
B15: RTD | C15: Esports Citizen | D15: Code Keeper | E15: 6 | I15: Dragon Slayer | N15: 15 | O15: 1 | T15: 15 | U15: 1
B16: RTD | C16: Esports Citizen | D16: Positve Voice | E16: 3 | I16: Duo Snatcher | R16: 3 | S16: 1 | T16: 3 | U16: 1
B17: RTD | C17: Digital skills | D17: Data Logger | E17: 6 | I17: End Of The Road | N17: 15 | O17: 1 | T17: 15 | U17: 1
B18: RTD | C18: Digital skills | D18: Prep Master | E18: 6 | I18: Goal Scorer | P18: 6 | Q18: 1 | T18: 6 | U18: 1
B19: RTD | C19: Digital skills | D19: Memory Maker | E19: 6 | I19: Goal Setter | P19: 3 | Q19: 1 | T19: 3 | U19: 1
B20: RTD | C20: Game Mastery | D20: End Of The Road | E20: 15 | I20: Learn In Action | P20: 6 | Q20: 1 | T20: 6 | U20: 1
B21: DFD | C21: Game Mastery | D21: Base Builder | E21: 3 | I21: Master Plan | N21: 6 | O21: 1 | T21: 6 | U21: 1
B22: DFD | C22: Game Mastery | D22: Nether Ready | E22: 6 | I22: Memory Maker | J22: 6 | K22: 1 | T22: 6 | U22: 1
B23: DFD | C23: Game Mastery | D23: Dragon Prepared | E23: 6 | I23: Mission Teamate | R23: 6 | S23: 1 | T23: 6 | U23: 1
B24: DFD | C24: Teamwork | D24: Team Planner | E24: 3 | I24: Nether Ready | N24: 6 | O24: 1 | T24: 6 | U24: 1
B25: DFD | C25: Teamwork | D25: Role Player | E25: 6 | I25: Player Performance | P25: 6 | Q25: 1 | T25: 6 | U25: 1
B26: DFD | C26: Teamwork | D26: Mission Teamate | E26: 6 | I26: Positve Voice | L26: 3 | M26: 1 | T26: 3 | U26: 1
B27: DFD | C27: Personal Development | D27: Goal Setter | E27: 3 | I27: Prep Master | J27: 6 | K27: 1 | T27: 6 | U27: 1
B28: DFD | C28: Personal Development | D28: Resilient | E28: 6 | I28: Reflection | P28: 6 | Q28: 1 | T28: 6 | U28: 1
B29: DFD | C29: Personal Development | D29: Reflection | E29: 6 | I29: Research Ranger | J29: 3 | K29: 1 | T29: 3 | U29: 1
B30: DFD | C30: Esports Citizen | D30: World Code | E30: 6 | I30: Resilient | P30: 6 | Q30: 1 | T30: 6 | U30: 1
B31: DFD | C31: Esports Citizen | D31: Top Citizen | E31: 6 | I31: Role Model | R31: 6 | S31: 1 | T31: 6 | U31: 1
B32: DFD | C32: Esports Citizen | D32: Supportive Teammate | E32: 3 | I32: Role Player | R32: 6 | S32: 1 | T32: 6 | U32: 1
B33: DFD | C33: Digital skills | D33: Document Designer | E33: 6 | I33: Skill Evaluation | N33: 6 | O33: 1 | T33: 6 | U33: 1
B34: DFD | C34: Digital skills | D34: Research Ranger | E34: 3 | I34: Storyteller | J34: 6 | K34: 1 | T34: 6 | U34: 1
B35: DFD | C35: Digital skills | D35: Storyteller | E35: 6 | I35: Supportive Teammate | L35: 3 | M35: 1 | T35: 3 | U35: 1
B36: DFD | C36: Game Mastery | D36: Dragon Slayer | E36: 15 | I36: Tactical Minds | R36: 6 | S36: 1 | T36: 6 | U36: 1
B37: DFD | C37: Teamwork | D37: Completed It First | E37: 15 | I37: Team Planner | R37: 3 | S37: 1 | T37: 3 | U37: 1
I38: Top Citizen | L38: 6 | M38: 1 | T38: 6 | U38: 1
I39: World Code | L39: 6 | M39: 1 | T39: 6 | U39: 1
I40: Grand Total | J40: 33 | K40: 6 | L40: 30 | M40: 6 | N40: 63 | O40: 8 | P40: 33 | Q40: 6 | R40: 45 | S40: 7 | T40: 204 | U40: 33

Sheet Road to Diamond- Module1
A1: Main Badge | B1: Sub Badge | C1: Points | D1: Description | E1: Skill 1 | F1: Skill 2 | G1: Skill 3 | H1: Skills
A2: Game Mastery | B2: Skill Evaluation | C2: 6 | D2: Take part in an individual skills evaluation session | E2: Confidence | F2: Resilience | G2: Decision Making | H2: Communication
A3: Game Mastery | B3: Master Plan | C3: 6 | D3: Create a game plan in relation to drop spot, rotation and loudouts | E3: Planning & Organising | F3: Decision Making | G3: Problem Solving | H3: Working with Others
A4: Game Mastery | B4: Basic Mechanics | C4: 6 | D4: Demonstrate basic mechanics | E4: Planning & Organising | F4: Decision Making | G4: Problem Solving
A5: Teamwork | B5: Duo Snatcher | C5: 3 | D5: Contribute to team name and agree on conduct | E5: Working with Others | F5: Creativity | G5: Confidence | H5: Leadership
A6: Teamwork | B6: Tactical Minds | C6: 6 | D6: Create communications stratagy | E6: Communication | F6: Confidence | G6: Working with Others | H6: Planning & Organising
A7: Teamwork | B7: Role Model | C7: 6 | D7: Understand your role within your team | E7: Working with Others | F7: Self-Management | G7: Confidence | H7: Problem Solving
A8: Personal Development | B8: Learn In Action | C8: 6 | D8: Focus on previous mistakes by practising improvements in a competetive match | E8: Decision Making | F8: Confidence | G8: Leadership | H8: Decision Making
A9: Personal Development | B9: Goal Scorer | C9: 6 | D9: Set a new goal | E9: Resilience | F9: Confidence | G9: Self-Management | H9: Creativity
A10: Personal Development | B10: Player Performance | C10: 6 | D10: Use replay review to identify mistakes in a competitive match | E10: Confidence | F10: Resilience | G10: Self-Management | H10: Confidence
A11: Esports Citizen | B11: Conduct Creator | C11: 6 | D11: Help create the group code of conduct | E11: Working with Others | F11: Resilience | G11: Problem Solving | H11: Self-Management
A12: Esports Citizen | B12: Code Keeper | C12: 6 | D12: Dont breech the group or duo conduct | E12: Self-Management | F12: Resilience | G12: Confidence | H12: Resilience
A13: Esports Citizen | B13: Positve Voice | C13: 3 | D13: Encourage other players or teams | E13: Working with Others | F13: Leadership | G13: Confidence | H13: Digital Literacy
A14: Digital skills | B14: Data Logger | C14: 6 | D14: Record stats in digital format | E14: Planning & Organising | F14: Creativity | G14: Digital Literacy
A15: Digital skills | B15: Prep Master | C15: 6 | D15: use online tools to plan your strategy | E15: Planning & Organising | F15: Digital Literacy | G15: Decision Making
A16: Digital skills | B16: Memory Maker | C16: 6 | D16: Take screenshots, clips and create notes about your journey | E16: Digital Literacy | F16: Planning & Organising | G16: Working with Others
A17: Game Mastery | B17: End Of The Road | C17: 15 | D17: Achieve diamond rank | E17: Digital Literacy | F17: Resilience | G17: Confidence

Sheet RTD Module1 - Schedule
A1: Week no | B1: Session Focus | C1: Sub-badge | D1: Link To Session Plan | E1: Link to Session Slides
A2: 1 | B2: Welcome/Settle In
A3: 2 | B3: Code of Conduct | C3: Conduct Creator
A4: 3 | B4: Player Evaluation | C4: Skill Evaluation
A5: 4 | B5: Player evaluation cont. | C5: Skill Evaluation
A6: 5 | B6: Duo Allocation | C6: Duo Snatcher
A7: 6 | B7: Team Roles | C7: Role Player
A8: 7 | B8: Practice Routines | C8: Basic Mechanics
A9: 8 | B9: Drop spot & Loot paths | C9: Master Plan
A10: 9 | B10: Goal Setting | C10: Goal Scorer
A11: 10 | B11: Stat tracking | C11: Data Logger
A12: 11 | B12: Ranked Grind | C12: End of the Road
A13: 12 | B13: Ranked Grind | C13: End of the Road
H18: Conduct Creator
H19: Skill Evaluation
H20: Skill Evaluation
H21: Duo Snatcher
H22: Role Player
H23: Basic Mechanics
H24: Master Plan
H25: Goal Scorer
H26: Data Logger
H27: End of the Road
H28: End of the Road

Sheet RTD Module 1 - Points Tracker
A2: Column 1 | B2: Sub Badge | C2: Points | D2: Player 1 | E2: Player 2 | F2: Player 3 | G2: Player 4 | H2: Player 5 | I2: Player 6 | J2: Player 7 | K2: Player 8 | L2: Player 9 | M2: Player 10 | N2: Player 11 | O2: Player 12 | P2: Player 13 | Q2: Player 14 | R2: Player 15 | S2: Player 16
A3: Game Mastery | B3: Legacy Points | D3: 68 | E3: 42 | F3: 12 | G3: 35 | H3: 20 | I3: 19 | J3: 62 | K3: 60 | L3: 20 | M3: 52 | N3: 42 | O3: 76 | P3: 28 | Q3: 26 | R3: 44 | S3: 62
A4: Teamwork | B4: Legacy Points | D4: 56 | E4: 38 | F4: 10 | G4: 38 | H4: 27 | I4: 27 | J4: 10 | K4: 56 | L4: 24 | M4: 56 | N4: 56 | O4: 56 | P4: 27 | Q4: 34 | R4: 10 | S4: 38
A5: Personal Development | B5: Legacy Points | D5: 45 | E5: 21 | G5: 24 | H5: 21 | I5: 21 | J5: 48 | K5: 48 | L5: 21 | M5: 48 | N5: 48 | O5: 48 | P5: 21 | Q5: 19 | R5: 45 | S5: 21
A6: Esports Citizen | B6: Legacy Points | D6: 28 | E6: 44 | F6: 8 | G6: 17 | H6: 17 | I6: 28 | J6: 44 | K6: 44 | L6: 19 | M6: 44 | N6: 28 | O6: 44 | P6: 28 | Q6: 8 | R6: 17 | S6: 28
A7: Digital skills | B7: Legacy Points | D7: 54 | E7: 31 | F7: 9 | G7: 9 | H7: 9 | I7: 23 | J7: 31 | K7: 54 | L7: 23 | M7: 54 | N7: 27 | O7: 54 | P7: 23 | Q7: 31 | R7: 31 | S7: 54
A8: Game Mastery | B8: Skill Evaluation | C8: 6 | D8: 6 | E8: 6 | F8: 6 | H8: 6 | I8: 6 | J8: 6 | L8: 6 | M8: 6 | N8: 6 | O8: 6 | P8: 6 | Q8: 6 | R8: 6 | S8: 6
A9: Game Mastery | B9: Master Plan | C9: 6 | D9: 6 | E9: 6 | F9: 6 | H9: 6 | I9: 6 | J9: 6 | K9: 6 | L9: 6 | M9: 6 | N9: 6 | O9: 6 | P9: 6 | Q9: 6 | R9: 6 | S9: 6
A10: Game Mastery | B10: Basic Mechanics | C10: 6 | D10: 6 | E10: 6 | F10: 6 | G10: 6 | H10: 6 | I10: 6 | J10: 6 | K10: 6 | L10: 6 | M10: 6 | N10: 6 | O10: 6 | P10: 6 | Q10: 6 | R10: 6 | S10: 6
A11: Teamwork | B11: Duo Snatcher | C11: 3 | D11: 3 | E11: 3 | F11: 3 | G11: 3 | H11: 3 | I11: 3 | J11: 3 | K11: 3 | L11: 3 | O11: 3 | Q11: 3 | R11: 3 | S11: 3
A12: Teamwork | B12: Tactical Minds | C12: 6 | D12: 6 | E12: 6 | F12: 6 | H12: 6 | J12: 6 | K12: 6 | M12: 6 | N12: 6 | O12: 6 | P12: 6 | R12: 6 | S12: 6
A13: Teamwork | B13: Role Player | C13: 6 | D13: 6 | E13: 6 | F13: 6 | G13: 6 | H13: 6 | I13: 6 | J13: 6 | K13: 6 | L13: 6 | M13: 6 | N13: 6 | O13: 6 | P13: 6 | Q13: 6 | R13: 6 | S13: 6
A14: Personal Development | B14: Learn In Action | C14: 6
A15: Personal Development | B15: Goal Scorer | C15: 6 | E15: 6 | F15: 6 | H15: 6 | I15: 6 | J15: 6 | K15: 6 | M15: 6 | N15: 6 | O15: 6 | P15: 6 | Q15: 6 | R15: 6 | S15: 6
A16: Personal Development | B16: Player Performance | C16: 6
A17: Esports Citizen | B17: Conduct Creator | C17: 6 | D17: 6 | E17: 6 | F17: 6 | G17: 6 | H17: 6 | I17: 6 | J17: 6 | K17: 6 | M17: 6 | N17: 6 | O17: 6 | P17: 6 | Q17: 6 | S17: 6
A18: Esports Citizen | B18: Code Keeper | C18: 6 | E18: 6 | G18: 6 | I18: 6 | J18: 6 | P18: 6 | Q18: 6
A19: Esports Citizen | B19: Positive Voice | C19: 3 | E19: 3 | G19: 3 | I19: 3 | J19: 3 | O19: 3 | P19: 3 | Q19: 3 | R19: 3
A20: Digital skills | B20: Data Logger | C20: 3
A21: Digital skills | B21: Prep Master | C21: 6 | D21: 6 | F21: 6 | G21: 6 | H21: 6 | J21: 6 | K21: 6 | L21: 6 | M21: 6 | N21: 6 | O21: 6 | P21: 6 | R21: 6 | S21: 6
A22: Digital skills | B22: Memory Maker | C22: 6
A23: Game Mastery | B23: End of The Road | C23: 15
A24: TOTAL | B24: =SUM(B8:B23) -> 0 | D24: =SUM(E3:E23) -> 230 | E24: =SUM(F3:F23) -> 90 | F24: =SUM(G3:G23) -> 159 | G24: =SUM(H3:H23) -> 145 | H24: =SUM(I3:I23) -> 166 | I24: =SUM(J3:J23) -> 255 | J24: =SUM(K3:K23) -> 307 | K24: =SUM(L3:L23) -> 140 | ... S24: =SUM(T3:T23) -> 0

Sheet Rocket League Player Points
A2: Badge Cat | B2: Player 1 | C2: Player 2 | D2: Player 3 | E2: Player 4 | F2: Player 5 | G2: Player 6 | H2: Player 7 | I2: Player 8 | J2: Player 9 | K2: Player 10 | L2: Player 11 | M2: Player 12 | N2: Player 13 | O2: Player 14 | P2: Player 15 | Q2: Player 16
A3: game mastery | B3: ='RTD Module 1 - Points Tracker'!D3+'RTD Module 1 - Points Tracker'!D8+'RTD Module 1 - Points Tracker'!D9+'RTD Module 1 - Points Tracker'!D10+'RTD Module 1 - Points Tracker'!D23 -> 86 | C3: ='RTD Module 1 - Points Tracker'!E3+'RTD Module 1 - Points Tracker'!E8+'RTD Module 1 - Points Tracker'!E9+'RTD Module 1 - Points Tracker'!E10+'RTD Module 1 - Points Tracker'!E23 -> 60 | D3: ='RTD Module 1 - Points Tracker'!F3+'RTD Module 1 - Points Tracker'!F8+'RTD Module 1 - Points Tracker'!F9+'RTD Module 1 - Points Tracker'!F10+'RTD Module 1 - Points Tracker'!F23 -> 30 | E3: ='RTD Module 1 - Points Tracker'!G3+'RTD Module 1 - Points Tracker'!G8+'RTD Module 1 - Points Tracker'!G9+'RTD Module 1 - Points Tracker'!G10+'RTD Module 1 - Points Tracker'!G23 -> 41 | F3: ='RTD Module 1 - Points Tracker'!H3+'RTD Module 1 - Points Tracker'!H8+'RTD Module 1 - Points Tracker'!H9+'RTD Module 1 - Points Tracker'!H10+'RTD Module 1 - Points Tracker'!H23 -> 38 | G3: ='RTD Module 1 - Points Tracker'!I3+'RTD Module 1 - Points Tracker'!I8+'RTD Module 1 - Points Tracker'!I9+'RTD Module 1 - Points Tracker'!I10+'RTD Module 1 - Points Tracker'!I23 -> 37 | H3: ='RTD Module 1 - Points Tracker'!J3+'RTD Module 1 - Points Tracker'!J8+'RTD Module 1 - Points Tracker'!J9+'RTD Module 1 - Points Tracker'!J10+'RTD Module 1 - Points Tracker'!J23 -> 80 | I3: ='RTD Module 1 - Points Tracker'!K3+'RTD Module 1 - Points Tracker'!K8+'RTD Module 1 - Points Tracker'!K9+'RTD Module 1 - Points Tracker'!K10+'RTD Module 1 - Points Tracker'!K23 -> 72 | ... Q3: ='RTD Module 1 - Points Tracker'!S3+'RTD Module 1 - Points Tracker'!S8+'RTD Module 1 - Points Tracker'!S9+'RTD Module 1 - Points Tracker'!S10+'RTD Module 1 - Points Tracker'!S23 -> 80
A4: TeamWork | B4: ='RTD Module 1 - Points Tracker'!D4+'RTD Module 1 - Points Tracker'!D11+'RTD Module 1 - Points Tracker'!D12+'RTD Module 1 - Points Tracker'!D13 -> 71 | C4: ='RTD Module 1 - Points Tracker'!E4+'RTD Module 1 - Points Tracker'!E11+'RTD Module 1 - Points Tracker'!E12+'RTD Module 1 - Points Tracker'!E13 -> 53 | D4: ='RTD Module 1 - Points Tracker'!F4+'RTD Module 1 - Points Tracker'!F11+'RTD Module 1 - Points Tracker'!F12+'RTD Module 1 - Points Tracker'!F13 -> 25 | E4: ='RTD Module 1 - Points Tracker'!G4+'RTD Module 1 - Points Tracker'!G11+'RTD Module 1 - Points Tracker'!G12+'RTD Module 1 - Points Tracker'!G13 -> 47 | F4: ='RTD Module 1 - Points Tracker'!H4+'RTD Module 1 - Points Tracker'!H11+'RTD Module 1 - Points Tracker'!H12+'RTD Module 1 - Points Tracker'!H13 -> 42 | G4: ='RTD Module 1 - Points Tracker'!I4+'RTD Module 1 - Points Tracker'!I11+'RTD Module 1 - Points Tracker'!I12+'RTD Module 1 - Points Tracker'!I13 -> 36 | H4: ='RTD Module 1 - Points Tracker'!J4+'RTD Module 1 - Points Tracker'!J11+'RTD Module 1 - Points Tracker'!J12+'RTD Module 1 - Points Tracker'!J13 -> 25 | I4: ='RTD Module 1 - Points Tracker'!K4+'RTD Module 1 - Points Tracker'!K11+'RTD Module 1 - Points Tracker'!K12+'RTD Module 1 - Points Tracker'!K13 -> 71 | ... Q4: ='RTD Module 1 - Points Tracker'!S4+'RTD Module 1 - Points Tracker'!S11+'RTD Module 1 - Points Tracker'!S12+'RTD Module 1 - Points Tracker'!S13 -> 53
A5: Personal Development | B5: ='RTD Module 1 - Points Tracker'!D5+'RTD Module 1 - Points Tracker'!D14+'RTD Module 1 - Points Tracker'!D15+'RTD Module 1 - Points Tracker'!D16 -> 45 | C5: ='RTD Module 1 - Points Tracker'!E5+'RTD Module 1 - Points Tracker'!E14+'RTD Module 1 - Points Tracker'!E15+'RTD Module 1 - Points Tracker'!E16 -> 27 | D5: ='RTD Module 1 - Points Tracker'!F5+'RTD Module 1 - Points Tracker'!F14+'RTD Module 1 - Points Tracker'!F15+'RTD Module 1 - Points Tracker'!F16 -> 6 | E5: ='RTD Module 1 - Points Tracker'!G5+'RTD Module 1 - Points Tracker'!G14+'RTD Module 1 - Points Tracker'!G15+'RTD Module 1 - Points Tracker'!G16 -> 24 | F5: ='RTD Module 1 - Points Tracker'!H5+'RTD Module 1 - Points Tracker'!H14+'RTD Module 1 - Points Tracker'!H15+'RTD Module 1 - Points Tracker'!H16 -> 27 | G5: ='RTD Module 1 - Points Tracker'!I5+'RTD Module 1 - Points Tracker'!I14+'RTD Module 1 - Points Tracker'!I15+'RTD Module 1 - Points Tracker'!I16 -> 27 | H5: ='RTD Module 1 - Points Tracker'!J5+'RTD Module 1 - Points Tracker'!J14+'RTD Module 1 - Points Tracker'!J15+'RTD Module 1 - Points Tracker'!J16 -> 54 | I5: ='RTD Module 1 - Points Tracker'!K5+'RTD Module 1 - Points Tracker'!K14+'RTD Module 1 - Points Tracker'!K15+'RTD Module 1 - Points Tracker'!K16 -> 54 | ... Q5: ='RTD Module 1 - Points Tracker'!S5+'RTD Module 1 - Points Tracker'!S14+'RTD Module 1 - Points Tracker'!S15+'RTD Module 1 - Points Tracker'!S16 -> 27
A6: Esports Citizen | B6: ='RTD Module 1 - Points Tracker'!D6+'RTD Module 1 - Points Tracker'!D17+'RTD Module 1 - Points Tracker'!D18+'RTD Module 1 - Points Tracker'!D19 -> 34 | C6: ='RTD Module 1 - Points Tracker'!E6+'RTD Module 1 - Points Tracker'!E17+'RTD Module 1 - Points Tracker'!E18+'RTD Module 1 - Points Tracker'!E19 -> 59 | D6: ='RTD Module 1 - Points Tracker'!F6+'RTD Module 1 - Points Tracker'!F17+'RTD Module 1 - Points Tracker'!F18+'RTD Module 1 - Points Tracker'!F19 -> 14 | E6: ='RTD Module 1 - Points Tracker'!G6+'RTD Module 1 - Points Tracker'!G17+'RTD Module 1 - Points Tracker'!G18+'RTD Module 1 - Points Tracker'!G19 -> 32 | F6: ='RTD Module 1 - Points Tracker'!H6+'RTD Module 1 - Points Tracker'!H17+'RTD Module 1 - Points Tracker'!H18+'RTD Module 1 - Points Tracker'!H19 -> 23 | G6: ='RTD Module 1 - Points Tracker'!I6+'RTD Module 1 - Points Tracker'!I17+'RTD Module 1 - Points Tracker'!I18+'RTD Module 1 - Points Tracker'!I19 -> 43 | H6: ='RTD Module 1 - Points Tracker'!J6+'RTD Module 1 - Points Tracker'!J17+'RTD Module 1 - Points Tracker'!J18+'RTD Module 1 - Points Tracker'!J19 -> 59 | I6: ='RTD Module 1 - Points Tracker'!K6+'RTD Module 1 - Points Tracker'!K17+'RTD Module 1 - Points Tracker'!K18+'RTD Module 1 - Points Tracker'!K19 -> 50 | ... Q6: ='RTD Module 1 - Points Tracker'!S6+'RTD Module 1 - Points Tracker'!S17+'RTD Module 1 - Points Tracker'!S18+'RTD Module 1 - Points Tracker'!S19 -> 34
A7: Digital Skills | B7: ='RTD Module 1 - Points Tracker'!D7+'RTD Module 1 - Points Tracker'!D20+'RTD Module 1 - Points Tracker'!D21+'RTD Module 1 - Points Tracker'!D22 -> 60 | C7: ='RTD Module 1 - Points Tracker'!E7+'RTD Module 1 - Points Tracker'!E20+'RTD Module 1 - Points Tracker'!E21+'RTD Module 1 - Points Tracker'!E22 -> 31 | D7: ='RTD Module 1 - Points Tracker'!F7+'RTD Module 1 - Points Tracker'!F20+'RTD Module 1 - Points Tracker'!F21+'RTD Module 1 - Points Tracker'!F22 -> 15 | E7: ='RTD Module 1 - Points Tracker'!G7+'RTD Module 1 - Points Tracker'!G20+'RTD Module 1 - Points Tracker'!G21+'RTD Module 1 - Points Tracker'!G22 -> 15 | F7: ='RTD Module 1 - Points Tracker'!H7+'RTD Module 1 - Points Tracker'!H20+'RTD Module 1 - Points Tracker'!H21+'RTD Module 1 - Points Tracker'!H22 -> 15 | G7: ='RTD Module 1 - Points Tracker'!I7+'RTD Module 1 - Points Tracker'!I20+'RTD Module 1 - Points Tracker'!I21+'RTD Module 1 - Points Tracker'!I22 -> 23 | H7: ='RTD Module 1 - Points Tracker'!J7+'RTD Module 1 - Points Tracker'!J20+'RTD Module 1 - Points Tracker'!J21+'RTD Module 1 - Points Tracker'!J22 -> 37 | I7: ='RTD Module 1 - Points Tracker'!K7+'RTD Module 1 - Points Tracker'!K20+'RTD Module 1 - Points Tracker'!K21+'RTD Module 1 - Points Tracker'!K22 -> 60 | ... Q7: ='RTD Module 1 - Points Tracker'!S7+'RTD Module 1 - Points Tracker'!S20+'RTD Module 1 - Points Tracker'!S21+'RTD Module 1 - Points Tracker'!S22 -> 60

Sheet Defeat The Ednder Dragon - MCMo
A1: Main Badge | B1: Sub Badge | C1: Points | D1: Description | E1: Skill 1 | F1: Skill 2 | G1: Skill 3 | H1: Skills
A2: Game Mastery | B2: Base Builder | C2: 3 | D2: Help build and set up a shared homebase (shelter, storage, food) | E2: Problem Solving | F2: Planning & Organising | G2: Working with Others | H2: Communication
A3: Game Mastery | B3: Nether Ready | C3: 6 | D3: Gather weapons, armour, and food to journey to the nether as listed in the team plan | E3: Resilience | F3: Self-Management | G3: Decision Making | H3: Working with Others
A4: Game Mastery | B4: Dragon Prepared | C4: 6 | D4: Understand and prepare for the Ender Dragon fight | E4: Planning & Organising | F4: Planning & Organising | G4: Digital Literacy
A5: Teamwork | B5: Team Planner | C5: 3 | D5: Work with the team to come up with an plan for each stage | E5: Working with Others | F5: Creativity | G5: Confidence | H5: Leadership
A6: Teamwork | B6: Role Player | C6: 6 | D6: Take on and stick to a team role across sessions | E6: Confidence | F6: Resilience | G6: Working with Others | H6: Planning & Organising
A7: Teamwork | B7: Mission Teamate | C7: 6 | D7: Work positively with others - adhere to the code of conduct | E7: Working with Others | F7: Self-Management | G7: Confidence | H7: Problem Solving
A8: Personal Development | B8: Goal Setter | C8: 3 | D8: Set a goal related to this challenge | E8: Decision Making | F8: Confidence | G8: Leadership | H8: Decision Making
A9: Personal Development | B9: Resilient | C9: 6 | D9: Keep trying after setbacks | E9: Resilience | F9: Confidence | G9: Self-Management | H9: Creativity
A10: Personal Development | B10: Reflection | C10: 6 | D10: Talk about what you learned and how you improved | E10: Confidence | F10: Resilience | G10: Self-Management | H10: Confidence
A11: Esports Citizen | B11: World Code | C11: 6 | D11: Help create the Code of Conduct | E11: Working with Others | F11: Resilience | G11: Problem Solving | H11: Self-Management
A12: Esports Citizen | B12: Top Citizen | C12: 6 | D12: Don't breech the code of conduct | E12: Self-Management | F12: Resilience | G12: Confidence | H12: Resilience
A13: Esports Citizen | B13: Supportive Teammate | C13: 3 | D13: Support another player to fulfill their role | E13: Working with Others | F13: Leadership | G13: Confidence | H13: Digital Literacy
A14: Digital skills | B14: Document Designer | C14: 6 | D14: Create a digital version of your team's plan | E14: Planning & Organising | F14: Creativity | G14: Digital Literacy
A15: Digital skills | B15: Research Ranger | C15: 3 | D15: Carry out online research to support your team's plan | E15: Planning & Organising | F15: Digital Literacy | G15: Decision Making
A16: Digital skills | B16: Storyteller | C16: 6 | D16: Take screenshots, clips and create notes about your journey | E16: Digital Literacy | F16: Planning & Organising | G16: Working with Others
A17: Game Mastery | B17: Dragon Slayer | C17: 15 | D17: Kill the ender dragon and complete the game | E17: Digital Literacy | F17: Resilience | G17: Confidence
A18: Teamwork | B18: Completed It First | C18: 15 | D18: Complete the game before the other team | E18: Working with Others | F18: Working with Others | G18: Confidence

Sheet DtED MCModule 1 - Points Tracke
A2: Column 1 | B2: Sub Badge | C2: Points | D2: Player 1 | E2: Player 2 | F2: Player 3 | G2: Player 4 | H2: Player 5 | I2: Player 6 | J2: Player 7 | K2: Player 8 | L2: Player 9 | M2: Player 10 | N2: Player 11 | O2: Player 12 | P2: Player 13 | Q2: Player 14 | R2: Player 15 | S2: Player 16
A3: Game Mastery | B3: Legacy Points | D3: 20 | E3: 13 | F3: 42 | G3: 48 | H3: 48 | I3: 36 | J3: 35 | K3: 12 | L3: 10 | M3: 44 | N3: 39 | O3: 22 | P3: 48 | R3: 12 | S3: 32
A4: Teamwork | B4: Legacy Points | D4: 18 | E4: 45 | F4: 38 | G4: 40 | H4: 40 | I4: 27 | J4: 38 | K4: 9 | L4: 12 | M4: 40 | N4: 40 | O4: 18 | P4: 40 | R4: 9 | S4: 40
A5: Personal Development | B5: Legacy Points | D5: 12 | E5: 22 | F5: 22 | G5: 22 | H5: 22 | I5: 20 | J5: 12 | K5: 12 | L5: 12 | M5: 22 | N5: 12 | O5: 12 | P5: 12 | R5: 12 | S5: 20
A6: Esports Citizen | B6: Legacy Points | D6: 21 | E6: 38 | F6: 21 | H6: 36 | I6: 38 | J6: 17 | K6: 21 | M6: 38 | N6: 21 | O6: 21 | P6: 21 | R6: 21 | S6: 21
A7: Digital skills | B7: Legacy Points | D7: 25 | E7: 20 | F7: 32 | G7: 20 | H7: 32 | I7: 32 | J7: 25 | K7: 25 | L7: 6 | M7: 25 | N7: 32 | O7: 32 | P7: 25 | R7: 25 | S7: 25
A8: Game Mastery | B8: Base Builder | C8: 3 | D8: 3 | E8: 3 | F8: 3 | G8: 3 | H8: 3 | K8: 3 | L8: 3 | M8: 3 | N8: 3 | O8: 3 | P8: 3 | Q8: 3 | R8: 3
A9: Game Mastery | B9: Nether Ready | C9: 6 | D9: 6 | E9: 6 | F9: 6 | G9: 6 | H9: 6 | I9: 6 | J9: 6 | K9: 6 | L9: 6 | M9: 6 | O9: 6 | P9: 6 | Q9: 6 | R9: 6 | S9: 6
A10: Game Mastery | B10: Dragon Prepared | C10: 6
A11: Teamwork | B11: Team Planner | C11: 3
A12: Teamwork | B12: Role Player | C12: 6 | D12: 6 | E12: 6 | F12: 6 | G12: 6 | H12: 6 | J12: 6 | K12: 6 | L12: 6 | M12: 6 | O12: 6 | P12: 6 | Q12: 6 | R12: 6 | S12: 6
A13: Teamwork | B13: Mission Teamate | C13: 6 | D13: 6 | E13: 6 | F13: 6 | J13: 6 | K13: 6 | O13: 6
A14: Personal Development | B14: Goal Setter | C14: 3 | D14: 3 | E14: 3 | F14: 3 | G14: 3 | H14: 3 | I14: 3 | J14: 3 | K14: 3 | L14: 3 | M14: 3 | N14: 3 | O14: 3 | P14: 3 | Q14: 3 | S14: 3
A15: Personal Development | B15: Resilient | C15: 6
A16: Personal Development | B16: Reflection | C16: 6
A17: Esports Citizen | B17: World Code | C17: 6 | D17: 6 | E17: 6 | F17: 6 | G17: 6 | H17: 6 | I17: 6 | J17: 6 | K17: 6 | L17: 6 | M17: 6 | N17: 6 | O17: 6 | P17: 6 | Q17: 6 | S17: 6
A18: Esports Citizen | B18: Top Citizen | C18: 6 | D18: 6 | E18: 6 | H18: 6 | K18: 6 | M18: 6 | O18: 6 | S18: 6
A19: Esports Citizen | B19: Supportive Teammate | C19: 3
A20: Digital skills | B20: Document Designer | C20: 6
A21: Digital skills | B21: Research Ranger | C21: 3 | D21: 3 | E21: 3 | F21: 3 | G21: 3 | H21: 3 | I21: 3 | J21: 3 | K21: 3 | L21: 3 | M21: 3 | N21: 3 | O21: 3 | P21: 3 | Q21: 3 | R21: 3 | S21: 3
A22: Digital skills | B22: Storyteller | C22: 6
A23: Game Mastery | B23: Dragon Slayer | C23: 15
A24: Teamwork | B24: Completed It First | C24: 15

Sheet Minecraft Player Points
A2: Badge Cat | B2: Player 1 | C2: Player 2 | D2: Player 3 | E2: Player 4 | F2: Player 5 | G2: Player 6 | H2: Player 7 | I2: Player 8 | J2: Player 9 | K2: Player 10 | L2: Player 11 | M2: Player 12 | N2: Player 13 | O2: Player 14 | P2: Player 15 | Q2: Player 16
A3: game mastery | B3: ='DtED MCModule 1 - Points Tracke'!D3+'DtED MCModule 1 - Points Tracke'!D8+'DtED MCModule 1 - Points Tracke'!D9+'DtED MCModule 1 - Points Tracke'!D10+'DtED MCModule 1 - Points Tracke'!D23 -> 29 | C3: ='DtED MCModule 1 - Points Tracke'!E3+'DtED MCModule 1 - Points Tracke'!E8+'DtED MCModule 1 - Points Tracke'!E9+'DtED MCModule 1 - Points Tracke'!E10+'DtED MCModule 1 - Points Tracke'!E23 -> 22 | D3: ='DtED MCModule 1 - Points Tracke'!F3+'DtED MCModule 1 - Points Tracke'!F8+'DtED MCModule 1 - Points Tracke'!F9+'DtED MCModule 1 - Points Tracke'!F10+'DtED MCModule 1 - Points Tracke'!F23 -> 51 | E3: ='DtED MCModule 1 - Points Tracke'!G3+'DtED MCModule 1 - Points Tracke'!G8+'DtED MCModule 1 - Points Tracke'!G9+'DtED MCModule 1 - Points Tracke'!G10+'DtED MCModule 1 - Points Tracke'!G23 -> 57 | F3: ='DtED MCModule 1 - Points Tracke'!H3+'DtED MCModule 1 - Points Tracke'!H8+'DtED MCModule 1 - Points Tracke'!H9+'DtED MCModule 1 - Points Tracke'!H10+'DtED MCModule 1 - Points Tracke'!H23 -> 57 | G3: ='DtED MCModule 1 - Points Tracke'!I3+'DtED MCModule 1 - Points Tracke'!I8+'DtED MCModule 1 - Points Tracke'!I9+'DtED MCModule 1 - Points Tracke'!I10+'DtED MCModule 1 - Points Tracke'!I23 -> 42 | H3: ='DtED MCModule 1 - Points Tracke'!J3+'DtED MCModule 1 - Points Tracke'!J8+'DtED MCModule 1 - Points Tracke'!J9+'DtED MCModule 1 - Points Tracke'!J10+'DtED MCModule 1 - Points Tracke'!J23 -> 41 | I3: ='DtED MCModule 1 - Points Tracke'!K3+'DtED MCModule 1 - Points Tracke'!K8+'DtED MCModule 1 - Points Tracke'!K9+'DtED MCModule 1 - Points Tracke'!K10+'DtED MCModule 1 - Points Tracke'!K23 -> 21 | ... Q3: ='DtED MCModule 1 - Points Tracke'!S3+'DtED MCModule 1 - Points Tracke'!S8+'DtED MCModule 1 - Points Tracke'!S9+'DtED MCModule 1 - Points Tracke'!S10+'DtED MCModule 1 - Points Tracke'!S23 -> 38
A4: TeamWork | B4: ='DtED MCModule 1 - Points Tracke'!D4+'DtED MCModule 1 - Points Tracke'!D11+'DtED MCModule 1 - Points Tracke'!D12+'DtED MCModule 1 - Points Tracke'!D13+'DtED MCModule 1 - Points Tracke'!D24 -> 30 | C4: ='DtED MCModule 1 - Points Tracke'!E4+'DtED MCModule 1 - Points Tracke'!E11+'DtED MCModule 1 - Points Tracke'!E12+'DtED MCModule 1 - Points Tracke'!E13+'DtED MCModule 1 - Points Tracke'!E24 -> 57 | D4: ='DtED MCModule 1 - Points Tracke'!F4+'DtED MCModule 1 - Points Tracke'!F11+'DtED MCModule 1 - Points Tracke'!F12+'DtED MCModule 1 - Points Tracke'!F13+'DtED MCModule 1 - Points Tracke'!F24 -> 50 | E4: ='DtED MCModule 1 - Points Tracke'!G4+'DtED MCModule 1 - Points Tracke'!G11+'DtED MCModule 1 - Points Tracke'!G12+'DtED MCModule 1 - Points Tracke'!G13+'DtED MCModule 1 - Points Tracke'!G24 -> 46 | F4: ='DtED MCModule 1 - Points Tracke'!H4+'DtED MCModule 1 - Points Tracke'!H11+'DtED MCModule 1 - Points Tracke'!H12+'DtED MCModule 1 - Points Tracke'!H13+'DtED MCModule 1 - Points Tracke'!H24 -> 46 | G4: ='DtED MCModule 1 - Points Tracke'!I4+'DtED MCModule 1 - Points Tracke'!I11+'DtED MCModule 1 - Points Tracke'!I12+'DtED MCModule 1 - Points Tracke'!I13+'DtED MCModule 1 - Points Tracke'!I24 -> 27 | H4: ='DtED MCModule 1 - Points Tracke'!J4+'DtED MCModule 1 - Points Tracke'!J11+'DtED MCModule 1 - Points Tracke'!J12+'DtED MCModule 1 - Points Tracke'!J13+'DtED MCModule 1 - Points Tracke'!J24 -> 50 | I4: ='DtED MCModule 1 - Points Tracke'!K4+'DtED MCModule 1 - Points Tracke'!K11+'DtED MCModule 1 - Points Tracke'!K12+'DtED MCModule 1 - Points Tracke'!K13+'DtED MCModule 1 - Points Tracke'!K24 -> 21 | ... Q4: ='DtED MCModule 1 - Points Tracke'!S4+'DtED MCModule 1 - Points Tracke'!S11+'DtED MCModule 1 - Points Tracke'!S12+'DtED MCModule 1 - Points Tracke'!S13+'DtED MCModule 1 - Points Tracke'!S24 -> 46
A5: Personal Development | B5: ='DtED MCModule 1 - Points Tracke'!D5+'DtED MCModule 1 - Points Tracke'!D14+'DtED MCModule 1 - Points Tracke'!D15+'DtED MCModule 1 - Points Tracke'!D16 -> 15 | C5: ='DtED MCModule 1 - Points Tracke'!E5+'DtED MCModule 1 - Points Tracke'!E14+'DtED MCModule 1 - Points Tracke'!E15+'DtED MCModule 1 - Points Tracke'!E16 -> 25 | D5: ='DtED MCModule 1 - Points Tracke'!F5+'DtED MCModule 1 - Points Tracke'!F14+'DtED MCModule 1 - Points Tracke'!F15+'DtED MCModule 1 - Points Tracke'!F16 -> 25 | E5: ='DtED MCModule 1 - Points Tracke'!G5+'DtED MCModule 1 - Points Tracke'!G14+'DtED MCModule 1 - Points Tracke'!G15+'DtED MCModule 1 - Points Tracke'!G16 -> 25 | F5: ='DtED MCModule 1 - Points Tracke'!H5+'DtED MCModule 1 - Points Tracke'!H14+'DtED MCModule 1 - Points Tracke'!H15+'DtED MCModule 1 - Points Tracke'!H16 -> 25 | G5: ='DtED MCModule 1 - Points Tracke'!I5+'DtED MCModule 1 - Points Tracke'!I14+'DtED MCModule 1 - Points Tracke'!I15+'DtED MCModule 1 - Points Tracke'!I16 -> 23 | H5: ='DtED MCModule 1 - Points Tracke'!J5+'DtED MCModule 1 - Points Tracke'!J14+'DtED MCModule 1 - Points Tracke'!J15+'DtED MCModule 1 - Points Tracke'!J16 -> 15 | I5: ='DtED MCModule 1 - Points Tracke'!K5+'DtED MCModule 1 - Points Tracke'!K14+'DtED MCModule 1 - Points Tracke'!K15+'DtED MCModule 1 - Points Tracke'!K16 -> 15 | ... Q5: ='DtED MCModule 1 - Points Tracke'!S5+'DtED MCModule 1 - Points Tracke'!S14+'DtED MCModule 1 - Points Tracke'!S15+'DtED MCModule 1 - Points Tracke'!S16 -> 23
A6: Esports Citizen | B6: ='DtED MCModule 1 - Points Tracke'!D6+'DtED MCModule 1 - Points Tracke'!D17+'DtED MCModule 1 - Points Tracke'!D18+'DtED MCModule 1 - Points Tracke'!D19 -> 33 | C6: ='DtED MCModule 1 - Points Tracke'!E6+'DtED MCModule 1 - Points Tracke'!E17+'DtED MCModule 1 - Points Tracke'!E18+'DtED MCModule 1 - Points Tracke'!E19 -> 50 | D6: ='DtED MCModule 1 - Points Tracke'!F6+'DtED MCModule 1 - Points Tracke'!F17+'DtED MCModule 1 - Points Tracke'!F18+'DtED MCModule 1 - Points Tracke'!F19 -> 27 | E6: ='DtED MCModule 1 - Points Tracke'!G6+'DtED MCModule 1 - Points Tracke'!G17+'DtED MCModule 1 - Points Tracke'!G18+'DtED MCModule 1 - Points Tracke'!G19 -> 6 | F6: ='DtED MCModule 1 - Points Tracke'!H6+'DtED MCModule 1 - Points Tracke'!H17+'DtED MCModule 1 - Points Tracke'!H18+'DtED MCModule 1 - Points Tracke'!H19 -> 48 | G6: ='DtED MCModule 1 - Points Tracke'!I6+'DtED MCModule 1 - Points Tracke'!I17+'DtED MCModule 1 - Points Tracke'!I18+'DtED MCModule 1 - Points Tracke'!I19 -> 44 | H6: ='DtED MCModule 1 - Points Tracke'!J6+'DtED MCModule 1 - Points Tracke'!J17+'DtED MCModule 1 - Points Tracke'!J18+'DtED MCModule 1 - Points Tracke'!J19 -> 23 | I6: ='DtED MCModule 1 - Points Tracke'!K6+'DtED MCModule 1 - Points Tracke'!K17+'DtED MCModule 1 - Points Tracke'!K18+'DtED MCModule 1 - Points Tracke'!K19 -> 33 | ... Q6: ='DtED MCModule 1 - Points Tracke'!S6+'DtED MCModule 1 - Points Tracke'!S17+'DtED MCModule 1 - Points Tracke'!S18+'DtED MCModule 1 - Points Tracke'!S19 -> 33
A7: Digital Skills | B7: ='DtED MCModule 1 - Points Tracke'!D7+'DtED MCModule 1 - Points Tracke'!D20+'DtED MCModule 1 - Points Tracke'!D21+'DtED MCModule 1 - Points Tracke'!D22 -> 28 | C7: ='DtED MCModule 1 - Points Tracke'!E7+'DtED MCModule 1 - Points Tracke'!E20+'DtED MCModule 1 - Points Tracke'!E21+'DtED MCModule 1 - Points Tracke'!E22 -> 23 | D7: ='DtED MCModule 1 - Points Tracke'!F7+'DtED MCModule 1 - Points Tracke'!F20+'DtED MCModule 1 - Points Tracke'!F21+'DtED MCModule 1 - Points Tracke'!F22 -> 35 | E7: ='DtED MCModule 1 - Points Tracke'!G7+'DtED MCModule 1 - Points Tracke'!G20+'DtED MCModule 1 - Points Tracke'!G21+'DtED MCModule 1 - Points Tracke'!G22 -> 23 | F7: ='DtED MCModule 1 - Points Tracke'!H7+'DtED MCModule 1 - Points Tracke'!H20+'DtED MCModule 1 - Points Tracke'!H21+'DtED MCModule 1 - Points Tracke'!H22 -> 35 | G7: ='DtED MCModule 1 - Points Tracke'!I7+'DtED MCModule 1 - Points Tracke'!I20+'DtED MCModule 1 - Points Tracke'!I21+'DtED MCModule 1 - Points Tracke'!I22 -> 35 | H7: ='DtED MCModule 1 - Points Tracke'!J7+'DtED MCModule 1 - Points Tracke'!J20+'DtED MCModule 1 - Points Tracke'!J21+'DtED MCModule 1 - Points Tracke'!J22 -> 28 | I7: ='DtED MCModule 1 - Points Tracke'!K7+'DtED MCModule 1 - Points Tracke'!K20+'DtED MCModule 1 - Points Tracke'!K21+'DtED MCModule 1 - Points Tracke'!K22 -> 28 | ... Q7: ='DtED MCModule 1 - Points Tracke'!S7+'DtED MCModule 1 - Points Tracke'!S20+'DtED MCModule 1 - Points Tracke'!S21+'DtED MCModule 1 - Points Tracke'!S22 -> 28
